package exception

fun main(args:Array<String>){
    val str = "abcd"
    // 예외 - 프로그램 실행 중 예상치 못하게 발생한 상황
    // 오류 메시지와 함께 강제 종료 됨
    val num = "str.toInt()"

    println(num)
}